Workbook

Sheet README
B2: EA-IRMS correction template
B4: Thermo Flash EA coupled to a Delta/253 IRMS. Takes the Isodat export and returns %C, %N, C:N, delta-13C and delta-15N, with every correction visible as a live formula. ea_irms 1.4.0.
B6: How to use it
B7: 1. Open the Raw sheet. Select rows 2 to 1001 and press Delete, then paste your Isodat export starting in cell A2. Do not paste over row 1: the headers there are what every other sheet looks for. The sheet ships loaded with the 2026-09-15 test run as a worked example, so delete that first.
B8: 2. Open Setup. Check the standards table against the certificates and against what the sequence actually called things. A material is recognised by the text in column A appearing anywhere in Identifier 1, so "Ace Drift" catches Ace Drift1 through Ace Drift 13. Matching ignores case.
B9: 3. Open Work and type sample masses in the yellow column F, in mg. Leave a cell empty to use the mass the export already carries in its Amount column. Without a mass there is no %C, %N or C:N for that row, though the isotope values still come out.
B10: 4. Read QC before you read anything else. It flags check standards that missed, samples outside the calibrated size range, blanks that cannot support a blank correction, a reference gas that moved during the run, and positions whose background rose right after an oversized sample.
B11: 5. Take the numbers from Results, with their uncertainties. Work is the audit trail behind them and Fits holds every fitted coefficient with its r-squared, residual scatter and, for the corrections, the test that decided whether it was applied.
B13: Colour
B14: Yellow cells with blue text are yours to fill in. Grey columns are machinery and can be ignored. Green columns are the reported values. Everything else is a formula, and overtyping one breaks that row silently, so work on a copy.
B16: What the sheets do
B17: Raw. Paste target, unaltered. Two grey helper columns label each peak record by channel and give it a key.
... B45: ea_irms 1.4.0. Built at the Wang Stable Isotope Biogeochemistry Lab, Boston College, and free to use and adapt. Cite the version when you publish data corrected with it.

Sheet Raw
A1: Row | B1: Identifier 1 | C1: Identifier 2 | D1: Peak Nr | E1: Amount | F1: Ampl 28 | G1: BGD 28 | H1: Area 28 | I1: Is Ref _ | J1: Ampl 44 | K1: Area 44 | L1: Peak Nr Flash TCD | M1: rArea Flash TCD | N1: d 15N/14N | O1: d 13C/12C | P1: BGD Flash TCD | R1: Channel | S1: Key | T1: grey helper columns, computed
A2: 56 | B2: blank capsule | E2: 0.397 | L2: 1 | M2: 83626 | P2: 2123 | R2: =IF($D2="","",IF($F2<>"","N",IF($J2<>"","C",""))) | S2: =IF($R2="","",$A2&"|"&$R2&"|"&$D2)
A3: 56 | B3: blank capsule | D3: 1 | E3: 0.397 | F3: 673 | G3: 23.3 | H3: 13.036 | I3: 0 | N3: -1.246 | R3: =IF($D3="","",IF($F3<>"","N",IF($J3<>"","C",""))) -> N | S3: =IF($R3="","",$A3&"|"&$R3&"|"&$D3) -> 56|N|1
A4: 56 | B4: blank capsule | D4: 2 | E4: 0.397 | F4: 677 | G4: 23.2 | H4: 13.038 | I4: 1 | N4: -1.25 | R4: =IF($D4="","",IF($F4<>"","N",IF($J4<>"","C",""))) -> N | S4: =IF($R4="","",$A4&"|"&$R4&"|"&$D4) -> 56|N|2
A5: 56 | B5: blank capsule | D5: 3 | E5: 0.397 | F5: 92 | G5: 25.7 | H5: 2.058 | I5: 0 | N5: -6.777 | R5: =IF($D5="","",IF($F5<>"","N",IF($J5<>"","C",""))) -> N | S5: =IF($R5="","",$A5&"|"&$R5&"|"&$D5) -> 56|N|3
A6: 56 | B6: blank capsule | D6: 4 | E6: 0.397 | I6: 1 | J6: 4720 | K6: 89.245 | O6: -25.22 | R6: =IF($D6="","",IF($F6<>"","N",IF($J6<>"","C",""))) -> C | S6: =IF($R6="","",$A6&"|"&$R6&"|"&$D6) -> 56|C|4
A7: 56 | B7: blank capsule | D7: 5 | E7: 0.397 | I7: 0 | J7: 4685 | K7: 89.236 | O7: -25.445 | R7: =IF($D7="","",IF($F7<>"","N",IF($J7<>"","C",""))) -> C | S7: =IF($R7="","",$A7&"|"&$R7&"|"&$D7) -> 56|C|5
A8: 56 | B8: blank capsule | D8: 6 | E8: 0.397 | I8: 0 | J8: 4746 | K8: 89.515 | O8: -25.553 | R8: =IF($D8="","",IF($F8<>"","N",IF($J8<>"","C",""))) -> C | S8: =IF($R8="","",$A8&"|"&$R8&"|"&$D8) -> 56|C|6
A9: 55 | B9: Ace Drift 13 | E9: 0.397 | L9: 1 | M9: 90981 | P9: 2121 | R9: =IF($D9="","",IF($F9<>"","N",IF($J9<>"","C",""))) | S9: =IF($R9="","",$A9&"|"&$R9&"|"&$D9)
A10: 55 | B10: Ace Drift 13 | E10: 0.397 | L10: 2 | M10: 683592 | P10: 2753 | R10: =IF($D10="","",IF($F10<>"","N",IF($J10<>"","C",""))) | S10: =IF($R10="","",$A10&"|"&$R10&"|"&$D10)
A11: 55 | B11: Ace Drift 13 | D11: 1 | E11: 0.397 | F11: 672 | G11: 23.3 | H11: 13.021 | I11: 0 | N11: -1.346 | R11: =IF($D11="","",IF($F11<>"","N",IF($J11<>"","C",""))) -> N | S11: =IF($R11="","",$A11&"|"&$R11&"|"&$D11) -> 55|N|1
A12: 55 | B12: Ace Drift 13 | D12: 2 | E12: 0.397 | F12: 677 | G12: 23.2 | H12: 13.038 | I12: 1 | N12: -1.25 | R12: =IF($D12="","",IF($F12<>"","N",IF($J12<>"","C",""))) -> N | S12: =IF($R12="","",$A12&"|"&$R12&"|"&$D12) -> 55|N|2
A13: 55 | B13: Ace Drift 13 | D13: 3 | E13: 0.397 | F13: 1555 | G13: 24 | H13: 28.314 | I13: 0 | N13: -6.395 | R13: =IF($D13="","",IF($F13<>"","N",IF($J13<>"","C",""))) -> N | S13: =IF($R13="","",$A13&"|"&$R13&"|"&$D13) -> 55|N|3
A14: 55 | B14: Ace Drift 13 | D14: 4 | E14: 0.397 | I14: 0 | J14: 5635 | K14: 128.087 | O14: -9.436 | R14: =IF($D14="","",IF($F14<>"","N",IF($J14<>"","C",""))) -> C | S14: =IF($R14="","",$A14&"|"&$R14&"|"&$D14) -> 55|C|4
A15: 55 | B15: Ace Drift 13 | D15: 5 | E15: 0.397 | I15: 1 | J15: 4749 | K15: 89.293 | O15: -25.22 | R15: =IF($D15="","",IF($F15<>"","N",IF($J15<>"","C",""))) -> C | S15: =IF($R15="","",$A15&"|"&$R15&"|"&$D15) -> 55|C|5
A16: 55 | B16: Ace Drift 13 | D16: 6 | E16: 0.397 | I16: 0 | J16: 4759 | K16: 89.385 | O16: -25.343 | R16: =IF($D16="","",IF($F16<>"","N",IF($J16<>"","C",""))) -> C | S16: =IF($R16="","",$A16&"|"&$R16&"|"&$D16) -> 55|C|6
A17: 55 | B17: Ace Drift 13 | D17: 7 | E17: 0.397 | I17: 0 | J17: 4753 | K17: 89.531 | O17: -25.405 | R17: =IF($D17="","",IF($F17<>"","N",IF($J17<>"","C",""))) -> C | S17: =IF($R17="","",$A17&"|"&$R17&"|"&$D17) -> 55|C|7
A18: 54 | B18: Ace Drift12 | E18: 0.38 | L18: 1 | M18: 89197 | P18: 2122 | R18: =IF($D18="","",IF($F18<>"","N",IF($J18<>"","C",""))) | S18: =IF($R18="","",$A18&"|"&$R18&"|"&$D18)
A19: 54 | B19: Ace Drift12 | E19: 0.38 | L19: 2 | M19: 655686 | P19: 2744 | R19: =IF($D19="","",IF($F19<>"","N",IF($J19<>"","C",""))) | S19: =IF($R19="","",$A19&"|"&$R19&"|"&$D19)
A20: 54 | B20: Ace Drift12 | D20: 1 | E20: 0.38 | F20: 673 | G20: 23 | H20: 13.018 | I20: 0 | N20: -1.255 | R20: =IF($D20="","",IF($F20<>"","N",IF($J20<>"","C",""))) -> N | S20: =IF($R20="","",$A20&"|"&$R20&"|"&$D20) -> 54|N|1
A21: 54 | B21: Ace Drift12 | D21: 2 | E21: 0.38 | F21: 677 | G21: 23 | H21: 13.035 | I21: 1 | N21: -1.25 | R21: =IF($D21="","",IF($F21<>"","N",IF($J21<>"","C",""))) -> N | S21: =IF($R21="","",$A21&"|"&$R21&"|"&$D21) -> 54|N|2
A22: 54 | B22: Ace Drift12 | D22: 3 | E22: 0.38 | F22: 1494 | G22: 23.8 | H22: 27.037 | I22: 0 | N22: -6.297 | R22: =IF($D22="","",IF($F22<>"","N",IF($J22<>"","C",""))) -> N | S22: =IF($R22="","",$A22&"|"&$R22&"|"&$D22) -> 54|N|3
A23: 54 | B23: Ace Drift12 | D23: 4 | E23: 0.38 | I23: 0 | J23: 5383 | K23: 122.82 | O23: -9.406 | R23: =IF($D23="","",IF($F23<>"","N",IF($J23<>"","C",""))) -> C | S23: =IF($R23="","",$A23&"|"&$R23&"|"&$D23) -> 54|C|4
A24: 54 | B24: Ace Drift12 | D24: 5 | E24: 0.38 | I24: 1 | J24: 4728 | K24: 89.218 | O24: -25.22 | R24: =IF($D24="","",IF($F24<>"","N",IF($J24<>"","C",""))) -> C | S24: =IF($R24="","",$A24&"|"&$R24&"|"&$D24) -> 54|C|5
A25: 54 | B25: Ace Drift12 | D25: 6 | E25: 0.38 | I25: 0 | J25: 4760 | K25: 89.44 | O25: -25.342 | R25: =IF($D25="","",IF($F25<>"","N",IF($J25<>"","C",""))) -> C | S25: =IF($R25="","",$A25&"|"&$R25&"|"&$D25) -> 54|C|6
A26: 54 | B26: Ace Drift12 | D26: 7 | E26: 0.38 | I26: 0 | J26: 4761 | K26: 89.366 | O26: -25.42 | R26: =IF($D26="","",IF($F26<>"","N",IF($J26<>"","C",""))) -> C | S26: =IF($R26="","",$A26&"|"&$R26&"|"&$D26) -> 54|C|7
A27: 53 | B27: Random | L27: 1 | M27: 82872 | P27: 2123 | R27: =IF($D27="","",IF($F27<>"","N",IF($J27<>"","C",""))) | S27: =IF($R27="","",$A27&"|"&$R27&"|"&$D27)
A28: 53 | B28: Random | D28: 1 | F28: 672 | G28: 23.3 | H28: 13.007 | I28: 0 | N28: -1.245 | R28: =IF($D28="","",IF($F28<>"","N",IF($J28<>"","C",""))) -> N | S28: =IF($R28="","",$A28&"|"&$R28&"|"&$D28) -> 53|N|1
A29: 53 | B29: Random | D29: 2 | F29: 676 | G29: 23.2 | H29: 13.02 | I29: 1 | N29: -1.25 | R29: =IF($D29="","",IF($F29<>"","N",IF($J29<>"","C",""))) -> N | S29: =IF($R29="","",$A29&"|"&$R29&"|"&$D29) -> 53|N|2
A30: 53 | B30: Random | D30: 3 | F30: 63 | G30: 25.7 | H30: 1.4 | I30: 0 | N30: -9.347 | R30: =IF($D30="","",IF($F30<>"","N",IF($J30<>"","C",""))) -> N | S30: =IF($R30="","",$A30&"|"&$R30&"|"&$D30) -> 53|N|3
A31: 53 | B31: Random | D31: 4 | I31: 1 | J31: 4723 | K31: 89.184 | O31: -25.22 | R31: =IF($D31="","",IF($F31<>"","N",IF($J31<>"","C",""))) -> C | S31: =IF($R31="","",$A31&"|"&$R31&"|"&$D31) -> 53|C|4
A32: 53 | B32: Random | D32: 5 | I32: 0 | J32: 4706 | K32: 89.357 | O32: -25.479 | R32: =IF($D32="","",IF($F32<>"","N",IF($J32<>"","C",""))) -> C | S32: =IF($R32="","",$A32&"|"&$R32&"|"&$D32) -> 53|C|5
A33: 53 | B33: Random | D33: 6 | I33: 0 | J33: 4735 | K33: 89.215 | O33: -25.543 | R33: =IF($D33="","",IF($F33<>"","N",IF($J33<>"","C",""))) -> C | S33: =IF($R33="","",$A33&"|"&$R33&"|"&$D33) -> 53|C|6
A34: 52 | B34: Random | L34: 1 | M34: 82808 | P34: 2126 | R34: =IF($D34="","",IF($F34<>"","N",IF($J34<>"","C",""))) | S34: =IF($R34="","",$A34&"|"&$R34&"|"&$D34)
A35: 52 | B35: Random | L35: 2 | M35: 544367 | P35: 2752 | R35: =IF($D35="","",IF($F35<>"","N",IF($J35<>"","C",""))) | S35: =IF($R35="","",$A35&"|"&$R35&"|"&$D35)
A36: 52 | B36: Random | D36: 1 | F36: 671 | G36: 23.2 | H36: 13.005 | I36: 0 | N36: -1.193 | R36: =IF($D36="","",IF($F36<>"","N",IF($J36<>"","C",""))) -> N | S36: =IF($R36="","",$A36&"|"&$R36&"|"&$D36) -> 52|N|1
A37: 52 | B37: Random | D37: 2 | F37: 677 | G37: 23.2 | H37: 13.02 | I37: 1 | N37: -1.25 | R37: =IF($D37="","",IF($F37<>"","N",IF($J37<>"","C",""))) -> N | S37: =IF($R37="","",$A37&"|"&$R37&"|"&$D37) -> 52|N|2
A38: 52 | B38: Random | D38: 3 | F38: 1236 | G38: 24 | H38: 22.447 | I38: 0 | N38: -5.883 | R38: =IF($D38="","",IF($F38<>"","N",IF($J38<>"","C",""))) -> N | S38: =IF($R38="","",$A38&"|"&$R38&"|"&$D38) -> 52|N|3
A39: 52 | B39: Random | D39: 4 | I39: 0 | J39: 4540 | K39: 101.638 | O39: -9.614 | R39: =IF($D39="","",IF($F39<>"","N",IF($J39<>"","C",""))) -> C | S39: =IF($R39="","",$A39&"|"&$R39&"|"&$D39) -> 52|C|4
A40: 52 | B40: Random | D40: 5 | I40: 1 | J40: 4733 | K40: 89.262 | O40: -25.22 | R40: =IF($D40="","",IF($F40<>"","N",IF($J40<>"","C",""))) -> C | S40: =IF($R40="","",$A40&"|"&$R40&"|"&$D40) -> 52|C|5
...

Sheet Setup
A1: Setup
A2: Yellow cells are yours. Everything else on this sheet is a label.
A4: Run information
A5: Run name | B5: 20260915 TestRun
A6: Run date | B6: 2026-09-15
A7: Analyst
A9: Processing options
A10: Blank correction | B10: Auto | G10: On / Off / Auto. Auto applies it only when at least three blanks agree to within 2 permil.
A11: Linearity correction | B11: Auto | G11: On / Off / Auto. Auto applies the fitted slope only when it differs from zero at the significance level below.
A12: Drift correction | B12: Auto | G12: On / Off / Auto. Auto applies the fitted slope only when it differs from zero at the significance level below.
A13: Drift model | B13: Row | G13: Row / Background / Auto. Auto takes the lower residual scatter, which is not an independent test. See the note under the table.
A14: First position to use in the drift fit | G14: Leave empty to use every position. QC suggests a value. The calibration anchors are never excluded, since they are always run early.
A15: Significance level for Auto | B15: 0.05 | G15: A slope is applied on Auto when its two-sided p-value is below this. The FIRMS guide asks that a correction be shown necessary before it is applied.
A16: Positions left out of the nitrogen drift fit | G16: Comma-separated autosampler positions, e.g. 59. Use it for a drift monitor QC calls an outlier when the cause is the capsule, not the instrument.
A17: Positions left out of the carbon drift fit | G17: Separate lists, because a capsule can go wrong in one element only.
A19: Flag thresholds
A20: Check standard offset (permil) | B20: 0.5 | G20: Flag a check standard further than this from its accepted value.
A21: Minimum Area 28 | G21: Leave empty to use the smallest linearity standard in the run.
A22: Minimum Area 44 | G22: Leave empty to use the smallest linearity standard in the run.
A23: Maximum Area 28 | G23: Leave empty to use the largest linearity standard in the run.
A24: Maximum Area 44 | G24: Leave empty to use the largest linearity standard in the run.
A25: Minimum peak area, x the blank | B25: 3 | G25: Below this multiple of the blank the blank correction amplifies rather than corrects. Leave empty to skip the check.
A26: Settled when background excess is under | B26: 0.1 | G26: Fraction of the run's starting excess left in the reference-peak background. Used only to suggest a first position and to flag.
A27: Drift monitor outlier, studentized residual | B27: 4 | G27: A drift monitor further than this from the line through the others, in units of their scatter, is flagged.
A28: Carryover: background rise after an oversized sample (mV) | B28: 2 | G28: Flags a position when one of the two before it is above the linearity range and its sample-peak background rose by more than this. Leave empty to skip the check.
A29: Uncertainty
A30: Sample repeatability, d15N (1 SD, permil) | G30: One analysis of one sample. Leave empty to use the pooled scatter of the anchor replicates in this run; better is the long-term SD of a matrix-matched in-house standard.
A31: Sample repeatability, d13C (1 SD, permil)
A32: Coverage factor k | B32: 2 | G32: Expanded uncertainty U = k x u. k = 2 is about 95 percent only when the replicates behind u are many; with a handful, take k from Student's t.
A34: Standards
A35: Accepted values below are the published USGS values as of 2026-09-16, and u is the 1-sigma uncertainty the producer lists. Check both against your certificates.
A36: Match text in Identifier 1 | B36: Role | C36: Accepted d13C | D36: Accepted d15N | E36: %C | F36: %N | G36: Material | H36: u(d13C) | I36: u(d15N)
A37: USGS 64 | B37: Anchor | C37: -40.81 | D37: 1.76 | E37: 32 | F37: 18.66 | G37: glycine | H37: 0.04 | I37: 0.06
A38: USGS 65 | B38: Anchor | C38: -20.29 | D38: 20.68 | E38: 32 | F38: 18.66 | G38: glycine | H38: 0.04 | I38: 0.06
A39: USGS 66 | B39: Check | C39: -0.67 | D39: 40.83 | E39: 32 | F39: 18.66 | G39: glycine | H39: 0.04 | I39: 0.06
A40: USGS 40 | B40: Check | C40: -26.39 | D40: -4.52 | E40: 40.82 | F40: 9.52 | G40: L-glutamic acid
A41: USGS 41a | B41: Check | C41: 36.55 | D41: 47.55 | E41: 40.82 | F41: 9.52 | G41: L-glutamic acid
A42: Ace Lin | B42: Linearity | E42: 71.09 | F42: 10.36 | G42: acetanilide, size series
A43: Ace Drift | B43: Drift | E43: 71.09 | F43: 10.36 | G43: acetanilide, drift monitor
A44: Ace Bypass | B44: Exclude | E44: 71.09 | F44: 10.36 | G44: bypass test
...

Sheet Work
A1: Work
A2: One row per autosampler position. Type sample masses in the yellow column F, in mg. Everything else is a formula. Grey columns are machinery.
A4: identification | E4: mass | H4: peak lookup | L4: as measured | S4: from the standards table | W4: nitrogen corrections | AB4: carbon corrections | AG4: elemental content | AM4: fit inputs and helpers, ignore | BI4: instrument settling | BK4: fit inputs and helpers, ignore | BS4: reference pulses | BX4: fit inputs and helpers, ignore | CL4: uncertainty, 1 SD and k x SD | CP4: fit inputs and helpers, ignore | DF4: chart feeds, ignore | EI4: carryover and settling helpers, ignore
A5: Row | B5: Identifier | C5: Std row | D5: Type | E5: Mass from export (mg) | F5: Mass entered (mg) | G5: Mass used (mg) | H5: peak N | I5: key N | J5: peak C | K5: key C | L5: Area 28 | M5: Ampl 28 | N5: BGD 28 | O5: d15N raw | P5: Area 44 | Q5: Ampl 44 | R5: d13C raw | S5: Accepted d15N | T5: Accepted d13C | U5: Certified %N | V5: Certified %C | W5: d15N blank-corr | X5: d15N linearity-corr | Y5: drift x (N) | Z5: d15N drift-corr | AA5: d15N calibrated | AB5: d13C blank-corr | AC5: d13C linearity-corr | AD5: drift x (C) | AE5: d13C drift-corr | AF5: d13C calibrated | AG5: ug N | AH5: ug C | AI5: %N | AJ5: %C | AK5: C:N molar | AL5: C:N mass | AM5: lin x N | AN5: lin y N | AO5: lin x C | AP5: lin y C | AQ5: drift x row | AR5: drift x bgd | AS5: drift y N | AT5: drift y C | AU5: cal x N | AV5: cal y N | AW5: cal x C | AX5: cal y C | AY5: kfit x N | AZ5: kfit y N | BA5: kfit x C | BB5: kfit y C | BC5: blank d15N | BD5: blank A28 | BE5: blank d13C | BF5: blank A44 | BG5: drift cal d15N | BH5: drift cal d13C | BI5: ref BGD 28 | BJ5: settling frac | BK5: drift x early | BL5: drift y early | BM5: drift x late | BN5: drift y late | BO5: stage raw | BP5: stage blank | BQ5: stage lin | BR5: stage drift | BS5: ref peak N | BT5: ref pulse d15N | BU5: ref flagged C | BV5: ref peak C | BW5: ref pulse d13C | BX5: excl N | BY5: excl C | BZ5: drift x N | CA5: drift x C | CB5: t drift N | CC5: t drift C | CD5: cal one N | CE5: cal dev N | CF5: cal res N | CG5: cal sq N | CH5: cal one C | CI5: cal dev C | CJ5: cal res C | CK5: cal sq C | CL5: u d15N | CM5: U d15N | CN5: u d13C | CO5: U d13C | CP5: settle streak | CQ5: ref x N | CR5: ref x C | CS5: match 1 | CT5: match 2 | CU5: match 3 | CV5: match 4 | CW5: match 5 | CX5: match 6 | CY5: match 7 | CZ5: match 8 | DA5: match 9 | DB5: match 10 | DC5: match 11 | DD5: match 12 | DE5: match 13 | DF5: ch pos | DG5: ch bgd | DH5: ch bgd sample | DI5: ch bgd monitor | DJ5: mon bgd | DK5: mon bgd x | DL5: ch lin x N | DM5: ch lin y N | DN5: ch samp x N | DO5: ch samp y N | DP5: ch drift used N | DQ5: ch drift out N | DR5: ch drift after N | DS5: ch cal y N | DT5: ch acc min N | DU5: ch acc max N | DV5: ch pulse N | DW5: ch lin x C | DX5: ch lin y C | DY5: ch samp x C | DZ5: ch samp y C | EA5: ch drift used C | EB5: ch drift out C | EC5: ch drift after C | ED5: ch cal y C | EE5: ch acc min C | EF5: ch acc max C | EG5: ch pulse C | EH5: ch carry | EI5: pos used | EJ5: oversized | EK5: exposed | EL5: carry ref | EM5: carry rise | EN5: carry flag | EO5: carry rank | EP5: after oversized | EQ5: ref first5 | ER5: settle start
A6: 1 | B6: =IFERROR(INDEX(Raw!$B$2:$B$1001,MATCH($A6,Raw!$A$2:$A$1001,0)),"") -> Blank Hole | C6: =IF($B6="","",MAX($CS6:$DE6)) -> 46 | D6: =IF($B6="","",IF($C6=0,"Sample",INDEX(Setup!$B$37:$B$49,$C6-36))) -> Exclude | E6: =IF($B6="","",IFERROR(IF(INDEX(Raw!$E$2:$E$1001,MATCH($A6,Raw!$A$2:$A$1001,0))=0,"",INDEX(Raw!$E$2:$E$1001,MATCH($A6,Raw!$A$2:$A$1001,0))),"")) | G6: =IF($B6="","",IF($F6<>"",$F6,IF($E6="","",$E6))) | H6: =IF($B6="","",SUMPRODUCT(MAX((Raw!$A$2:$A$1001=$A6)*(Raw!$R$2:$R$1001="N")*Raw!$D$2:$D$1001))) -> 3 | I6: =IF(OR($H6="",$H6=0),"",$A6&"|N|"&$H6) -> 1|N|3 | J6: =IF($B6="","",SUMPRODUCT(MIN((Raw!$A$2:$A$1001=$A6)*(Raw!$R$2:$R$1001="C")*Raw!$D$2:$D$1001+(1-(Raw!$A$2:$A$1001=$A6)*(Raw!$R$2:$R$1001="C"))*9999))) -> 4 | K6: =IF(OR($J6="",$J6=0,$J6=9999),"",$A6&"|C|"&$J6) -> 1|C|4 | L6: =IF($I6="","",IF(INDEX(Raw!$I$2:$I$1001,MATCH($I6,Raw!$S$2:$S$1001,0))<>0,"",INDEX(Raw!$H$2:$H$1001,MATCH($I6,Raw!$S$2:$S$1001,0)))) -> 6.018 | M6: =IF($I6="","",IF(INDEX(Raw!$I$2:$I$1001,MATCH($I6,Raw!$S$2:$S$1001,0))<>0,"",INDEX(Raw!$F$2:$F$1001,MATCH($I6,Raw!$S$2:$S$1001,0)))) -> 217 | N6: =IF($I6="","",IF(INDEX(Raw!$I$2:$I$1001,MATCH($I6,Raw!$S$2:$S$1001,0))<>0,"",INDEX(Raw!$G$2:$G$1001,MATCH($I6,Raw!$S$2:$S$1001,0)))) -> 38.6 | O6: =IF($I6="","",IF(INDEX(Raw!$I$2:$I$1001,MATCH($I6,Raw!$S$2:$S$1001,0))<>0,"",INDEX(Raw!$N$2:$N$1001,MATCH($I6,Raw!$S$2:$S$1001,0)))) -> 3.728 | P6: =IF($K6="","",IF(INDEX(Raw!$I$2:$I$1001,MATCH($K6,Raw!$S$2:$S$1001,0))<>0,"",INDEX(Raw!$K$2:$K$1001,MATCH($K6,Raw!$S$2:$S$1001,0)))) | Q6: =IF($K6="","",IF(INDEX(Raw!$I$2:$I$1001,MATCH($K6,Raw!$S$2:$S$1001,0))<>0,"",INDEX(Raw!$J$2:$J$1001,MATCH($K6,Raw!$S$2:$S$1001,0)))) | R6: =IF($K6="","",IF(INDEX(Raw!$I$2:$I$1001,MATCH($K6,Raw!$S$2:$S$1001,0))<>0,"",INDEX(Raw!$O$2:$O$1001,MATCH($K6,Raw!$S$2:$S$1001,0)))) | S6: =IF($B6="","",IF($C6=0,"",IF(INDEX(Setup!$D$37:$D$49,$C6-36)="","",INDEX(Setup!$D$37:$D$49,$C6-36)))) | T6: =IF($B6="","",IF($C6=0,"",IF(INDEX(Setup!$C$37:$C$49,$C6-36)="","",INDEX(Setup!$C$37:$C$49,$C6-36)))) | U6: =IF($B6="","",IF($C6=0,"",IF(INDEX(Setup!$F$37:$F$49,$C6-36)="","",INDEX(Setup!$F$37:$F$49,$C6-36)))) | V6: =IF($B6="","",IF($C6=0,"",IF(INDEX(Setup!$E$37:$E$49,$C6-36)="","",INDEX(Setup!$E$37:$E$49,$C6-36)))) | W6: =IF($O6="","",IF(OR(Fits!$C$5<>"Yes",$D6="Blank",$L6<=Fits!$B$6),$O6,($L6*$O6-Fits!$B$6*Fits!$B$7)/($L6-Fits!$B$6))) -> 3.728 | X6: =IF($W6="","",$W6-Fits!$B$20*($L6-Fits!$B$16)) -> 3.728 | Y6: =IF($W6="","",IF(OR(Fits!$B$38="Row",$BI6=""),$A6,$BI6)) -> 1 | Z6: =IF($X6="","",$X6-Fits!$B$39*($Y6-Fits!$B$40)) -> 3.2445113 | AA6: =IF(OR($Z6="",Fits!$B$55<2),"",Fits!$B$56*$Z6+Fits!$B$57) -> 4.3580771 | AB6: =IF($R6="","",IF(OR(Fits!$C$9<>"Yes",$D6="Blank",$P6<=Fits!$B$10),$R6,($P6*$R6-Fits!$B$10*Fits!$B$11)/($P6-Fits!$B$10))) | AC6: =IF($AB6="","",$AB6-Fits!$B$28*($P6-Fits!$B$24)) | AD6: =IF($AB6="","",IF(OR(Fits!$B$50="Row",$BI6=""),$A6,$BI6)) | AE6: =IF($AC6="","",$AC6-Fits!$B$51*($AD6-Fits!$B$52)) | AF6: =IF(OR($AE6="",Fits!$B$62<2),"",Fits!$B$63*$AE6+Fits!$B$64) | AG6: =IF(OR($L6="",Fits!$B$69<3),"",($L6-Fits!$B$71)/Fits!$B$70) -> 6.6623686 | AH6: =IF(OR($P6="",Fits!$B$75<3),"",($P6-Fits!$B$77)/Fits!$B$76) | AI6: =IF(OR($AG6="",$G6="",$G6=0),"",$AG6/($G6*1000)*100) | AJ6: =IF(OR($AH6="",$G6="",$G6=0),"",$AH6/($G6*1000)*100) | AK6: =IF(OR($AG6="",$AH6="",$AG6<=0),"",($AH6/Setup!$B$52)/($AG6/Setup!$B$53)) | AL6: =IF(OR($AG6="",$AH6="",$AG6<=0),"",$AH6/$AG6) | AM6: =IF($D6="Linearity",IF($L6="","",$L6),"") | AN6: =IF($D6="Linearity",IF($W6="","",$W6),"") | AO6: =IF($D6="Linearity",IF($P6="","",$P6),"") | AP6: =IF($D6="Linearity",IF($AB6="","",$AB6),"") | AQ6: =IF($D6="Drift",IF($A6<IF(Setup!$B$14="",0,Setup!$B$14),"",$A6),"") | AR6: =IF($D6="Drift",IF($A6<IF(Setup!$B$14="",0,Setup!$B$14),"",IF($BI6="","",$BI6)),"") | AS6: =IF($D6="Drift",IF($A6<IF(Setup!$B$14="",0,Setup!$B$14),"",IF(OR($X6="",$BX6=1),"",$X6)),"") | AT6: =IF($D6="Drift",IF($A6<IF(Setup!$B$14="",0,Setup!$B$14),"",IF(OR($AC6="",$BY6=1),"",$AC6)),"") | AU6: =IF($D6="Anchor",IF(OR($Z6="",$S6=""),"",$Z6),"") | AV6: =IF($D6="Anchor",IF(OR($Z6="",$S6=""),"",$S6),"") | AW6: =IF($D6="Anchor",IF(OR($AE6="",$T6=""),"",$AE6),"") | AX6: =IF($D6="Anchor",IF(OR($AE6="",$T6=""),"",$T6),"") | AY6: =IF(OR($D6="Blank",$D6="Exclude",$D6="Sample",$D6="",$G6="",$U6="",$L6=""),"",$G6*1000*$U6/100) | AZ6: =IF($AY6="","",$L6) | BA6: =IF(OR($D6="Blank",$D6="Exclude",$D6="Sample",$D6="",$G6="",$V6="",$P6=""),"",$G6*1000*$V6/100) | BB6: =IF($BA6="","",$P6) | BC6: =IF(AND($D6="Blank",$L6<>""),$O6,"") | BD6: =IF($BC6="","",$L6) | BE6: =IF(AND($D6="Blank",$P6<>""),$R6,"") | BF6: =IF($BE6="","",$P6) | BG6: =IF(AND($D6="Drift",$BX6<>1),IF($AA6="","",$AA6),"") | BH6: =IF(AND($D6="Drift",$BY6<>1),IF($AF6="","",$AF6),"") | BI6: =IF($B6="","",IFERROR(INDEX(Raw!$G$2:$G$1001,MATCH($A6&"|N|"&SUMPRODUCT(MAX((Raw!$A$2:$A$1001=$A6)*(Raw!$R$2:$R$1001="N")*(Raw!$I$2:$I$1001=1)*Raw!$D$2:$D$1001)),Raw!$S$2:$S$1001,0)),"")) -> 34.2 | BJ6: =IF(OR($BI6="",Fits!$B$85<=0),"",($BI6-Fits!$B$83)/Fits!$B$85) -> 1 | BK6: =IF($AS6="","",IF($A6>=Fits!$B$86,"",$A6)) | BL6: =IF($BK6="","",$X6) | BM6: =IF($AS6="","",IF($A6<Fits!$B$86,"",$A6)) | BN6: =IF($BM6="","",$X6) | BO6: =IF(AND($D6="Drift",$BX6<>1),IF($O6="","",$O6),"") | BP6: =IF(AND($D6="Drift",$BX6<>1),IF($W6="","",$W6),"") | BQ6: =IF(AND($D6="Drift",$BX6<>1),IF($X6="","",$X6),"") | BR6: =IF(AND($D6="Drift",$BX6<>1),IF($Z6="","",$Z6),"") | BS6: =IF(OR($B6="",$H6=""),"",SUMPRODUCT(MIN((Raw!$A$2:$A$1001=$A6)*(Raw!$R$2:$R$1001="N")*(Raw!$I$2:$I$1001=0)*(Raw!$D$2:$D$1001<$H6)*Raw!$D$2:$D$1001+(1-(Raw!$A$2:$A$1001=$A6)*(Raw!$R$2:$R$1001="N")*(Raw!$I$2:$I$1001=0)*(Raw!$D$2:$D$1001<$H6))*9999))) -> 1 | BT6: =IF(OR($BS6="",$BS6=9999,$BS6=0),"",IFERROR(INDEX(Raw!$N$2:$N$1001,MATCH($A6&"|N|"&$BS6,Raw!$S$2:$S$1001,0)),"")) -> -1.217 | BU6: =IF($B6="","",SUMPRODUCT(MIN((Raw!$A$2:$A$1001=$A6)*(Raw!$R$2:$R$1001="C")*(Raw!$I$2:$I$1001=1)*Raw!$D$2:$D$1001+(1-(Raw!$A$2:$A$1001=$A6)*(Raw!$R$2:$R$1001="C")*(Raw!$I$2:$I$1001=1))*9999))) -> 4 | BV6: =IF(OR($BU6="",$BU6=9999),"",SUMPRODUCT(MIN((Raw!$A$2:$A$1001=$A6)*(Raw!$R$2:$R$1001="C")*(Raw!$I$2:$I$1001=0)*(Raw!$D$2:$D$1001>$BU6)*Raw!$D$2:$D$1001+(1-(Raw!$A$2:$A$1001=$A6)*(Raw!$R$2:$R$1001="C")*(Raw!$I$2:$I$1001=0)*(Raw!$D$2:$D$1001>$BU6))*9999))) -> 5 | BW6: =IF(OR($BV6="",$BV6=9999,$BV6=0),"",IFERROR(INDEX(Raw!$O$2:$O$1001,MATCH($A6&"|C|"&$BV6,Raw!$S$2:$S$1001,0)),"")) -> -25.736 | BX6: =IF($B6="","",IF(ISNUMBER(SEARCH(","&$A6&",",","&SUBSTITUTE(Setup!$B$16," ","")&",")),1,0)) -> 0 | BY6: =IF($B6="","",IF(ISNUMBER(SEARCH(","&$A6&",",","&SUBSTITUTE(Setup!$B$17," ","")&",")),1,0)) -> 0 | BZ6: =IF($AS6="","",IF(Fits!$B$38="Row",$AQ6,IF($AR6="","",$AR6))) | CA6: =IF($AT6="","",IF(Fits!$B$50="Row",$AQ6,IF($AR6="","",$AR6))) | CB6: =IF(OR($D6<>"Drift",$X6="",$A6<IF(Setup!$B$14="",0,Setup!$B$14),Fits!$B$107<3,Fits!$B$110="",Fits!$B$109=0,IF(Fits!$B$38="Row",$AQ6,$AR6)=""),"",IF($BX6=1,IF(OR(Fits!$B$111="",Fits!$B$111=0),"",($X6-(IF(Fits!$B$38="Row",Fits!$B$32,Fits!$B$35)*IF(Fits!$B$38="Row",$AQ6,$AR6)+Fits!$B$110))/(Fits!$B$111*SQRT(1+(1/Fits!$B$107+(IF(Fits!$B$38="Row",$AQ6,$AR6)-Fits!$B$108)^2/Fits!$B$109)))),IF(OR(Fits!$B$107<4,(1/Fits!$B$107+(IF(Fits!$B$38="Row",$AQ6,$AR6)-Fits!$B$108)^2/Fits!$B$109)>=1),"",IF((Fits!$B$116-($X6-(IF(Fits!$B$38="Row",Fits!$B$32,Fits!$B$35)*IF(Fits!$B$38="Row",$AQ6,$AR6)+Fits!$B$110))^2/(1-(1/Fits!$B$107+(IF(Fits!$B$38="Row",$AQ6,$AR6)-Fits!$B$108)^2/Fits!$B$109)))<=0,"",($X6-(IF(Fits!$B$38="Row",Fits!$B$32,Fits!$B$35)*IF(Fits!$B$38="Row",$AQ6,$AR6)+Fits!$B$110))/(SQRT((Fits!$B$116-($X6-(IF(Fits!$B$38="Row",Fits!$B$32,Fits!$B$35)*IF(Fits!$B$38="Row",$AQ6,$AR6)+Fits!$B$110))^2/(1-(1/Fits!$B$107+(IF(Fits!$B$38="Row",$AQ6,$AR6)-Fits!$B$108)^2/Fits!$B$109)))/(Fits!$B$107-3))*SQRT(1-(1/Fits!$B$107+(IF(Fits!$B$38="Row",$AQ6,$AR6)-Fits!$B$108)^2/Fits!$B$109))))))) | CC6: =IF(OR($D6<>"Drift",$AC6="",$A6<IF(Setup!$B$14="",0,Setup!$B$14),Fits!$B$120<3,Fits!$B$123="",Fits!$B$122=0,IF(Fits!$B$50="Row",$AQ6,$AR6)=""),"",IF($BY6=1,IF(OR(Fits!$B$124="",Fits!$B$124=0),"",($AC6-(IF(Fits!$B$50="Row",Fits!$B$44,Fits!$B$47)*IF(Fits!$B$50="Row",$AQ6,$AR6)+Fits!$B$123))/(Fits!$B$124*SQRT(1+(1/Fits!$B$120+(IF(Fits!$B$50="Row",$AQ6,$AR6)-Fits!$B$121)^2/Fits!$B$122)))),IF(OR(Fits!$B$120<4,(1/Fits!$B$120+(IF(Fits!$B$50="Row",$AQ6,$AR6)-Fits!$B$121)^2/Fits!$B$122)>=1),"",IF((Fits!$B$129-($AC6-(IF(Fits!$B$50="Row",Fits!$B$44,Fits!$B$47)*IF(Fits!$B$50="Row",$AQ6,$AR6)+Fits!$B$123))^2/(1-(1/Fits!$B$120+(IF(Fits!$B$50="Row",$AQ6,$AR6)-Fits!$B$121)^2/Fits!$B$122)))<=0,"",($AC6-(IF(Fits!$B$50="Row",Fits!$B$44,Fits!$B$47)*IF(Fits!$B$50="Row",$AQ6,$AR6)+Fits!$B$123))/(SQRT((Fits!$B$129-($AC6-(IF(Fits!$B$50="Row",Fits!$B$44,Fits!$B$47)*IF(Fits!$B$50="Row",$AQ6,$AR6)+Fits!$B$123))^2/(1-(1/Fits!$B$120+(IF(Fits!$B$50="Row",$AQ6,$AR6)-Fits!$B$121)^2/Fits!$B$122)))/(Fits!$B$120-3))*SQRT(1-(1/Fits!$B$120+(IF(Fits!$B$50="Row",$AQ6,$AR6)-Fits!$B$121)^2/Fits!$B$122))))))) | CD6: =IF($AU6="","",1) | CE6: =IF($AU6="","",$AU6-Fits!$B$133) | CF6: =IF($AU6="","",($AV6-(Fits!$B$56*$AU6+Fits!$B$57))-Fits!$B$56*($AU6-Fits!$B$133)) | CG6: =IF($AU6="","",$AU6^2) | CH6: =IF($AW6="","",1) | CI6: =IF($AW6="","",$AW6-Fits!$B$153) | CJ6: =IF($AW6="","",($AX6-(Fits!$B$63*$AW6+Fits!$B$64))-Fits!$B$63*($AW6-Fits!$B$153)) | CK6: =IF($AW6="","",$AW6^2) | CL6: =IF(OR($Z6="",Fits!$B$55<3,Fits!$B$133="",Fits!$B$134="",Fits!$B$134=0,Fits!$B$136=""),"",SQRT((Fits!$B$136*Fits!$B$56)^2+SUMPRODUCT((Fits!$J$163:$J$175*(Fits!$B$163:$B$175/Fits!$B$55+Fits!$H$163:$H$175*($Z6-Fits!$B$133)/Fits!$B$134))^2)+SUMPRODUCT((Fits!$G$163:$G$175*(($Z6-Fits!$B$133)*Fits!$I$163:$I$175/Fits!$B$134-Fits!$B$163:$B$175*Fits!$B$56/Fits!$B$55))^2))) -> 0.20924701 | CM6: =IF($CL6="","",Setup!$B$32*$CL6) -> 0.41849402 | CN6: =IF(OR($AE6="",Fits!$B$62<3,Fits!$B$153="",Fits!$B$154="",Fits!$B$154=0,Fits!$B$156=""),"",SQRT((Fits!$B$156*Fits!$B$63)^2+SUMPRODUCT((Fits!$J$183:$J$195*(Fits!$B$183:$B$195/Fits!$B$62+Fits!$H$183:$H$195*($AE6-Fits!$B$153)/Fits!$B$154))^2)+SUMPRODUCT((Fits!$G$183:$G$195*(($AE6-Fits!$B$153)*Fits!$I$183:$I$195/Fits!$B$154-Fits!$B$183:$B$195*Fits!$B$63/Fits!$B$62))^2))) | CO6: =IF($CN6="","",Setup!$B$32*$CN6) | CP6: =IF(OR(NOT(ISNUMBER($BJ6)),$EK6=1),0,IF($BJ6<=Setup!$B$26,1,0)) -> 0 | CQ6: =IF($BT6="","",$A6) -> 1 | CR6: =IF($BW6="","",$A6) -> 1 | CS6: =IF($B6="","",IF(Setup!$A$37="",0,IF(ISNUMBER(SEARCH(Setup!$A$37,$B6)),37,0))) -> 0 | CT6: =IF($B6="","",IF(Setup!$A$38="",0,IF(ISNUMBER(SEARCH(Setup!$A$38,$B6)),38,0))) -> 0 | CU6: =IF($B6="","",IF(Setup!$A$39="",0,IF(ISNUMBER(SEARCH(Setup!$A$39,$B6)),39,0))) -> 0 | CV6: =IF($B6="","",IF(Setup!$A$40="",0,IF(ISNUMBER(SEARCH(Setup!$A$40,$B6)),40,0))) -> 0 | CW6: =IF($B6="","",IF(Setup!$A$41="",0,IF(ISNUMBER(SEARCH(Setup!$A$41,$B6)),41,0))) -> 0 | CX6: =IF($B6="","",IF(Setup!$A$42="",0,IF(ISNUMBER(SEARCH(Setup!$A$42,$B6)),42,0))) -> 0 | CY6: =IF($B6="","",IF(Setup!$A$43="",0,IF(ISNUMBER(SEARCH(Setup!$A$43,$B6)),43,0))) -> 0 | CZ6: =IF($B6="","",IF(Setup!$A$44="",0,IF(ISNUMBER(SEARCH(Setup!$A$44,$B6)),44,0))) -> 0 | DA6: =IF($B6="","",IF(Setup!$A$45="",0,IF(ISNUMBER(SEARCH(Setup!$A$45,$B6)),45,0))) -> 0 | DB6: =IF($B6="","",IF(Setup!$A$46="",0,IF(ISNUMBER(SEARCH(Setup!$A$46,$B6)),46,0))) -> 46 | DC6: =IF($B6="","",IF(Setup!$A$47="",0,IF(ISNUMBER(SEARCH(Setup!$A$47,$B6)),47,0))) -> 0 | DD6: =IF($B6="","",IF(Setup!$A$48="",0,IF(ISNUMBER(SEARCH(Setup!$A$48,$B6)),48,0))) -> 0 | DE6: =IF($B6="","",IF(Setup!$A$49="",0,IF(ISNUMBER(SEARCH(Setup!$A$49,$B6)),49,0))) -> 0 | DF6: =IF($B6="",NA(),$A6) -> 1 | DG6: =IF($BI6="",NA(),$BI6) -> 34.2 | DH6: =IF($N6="",NA(),$N6) -> 38.6 | DI6: =IF(AND($D6="Drift",$N6<>""),$N6,NA()) -> #N/A | DJ6: =IF(AND($D6="Drift",$N6<>""),$N6,"") | DK6: =IF($DJ6="","",$A6) | DL6: =IF($AN6="",NA(),$AM6) -> #N/A | DM6: =IF($AN6="",NA(),$AN6) -> #N/A | DN6: =IF(AND($D6="Sample",$L6<>""),$L6,NA()) -> #N/A | DO6: =IF(AND($D6="Sample",$L6<>"",Fits!$B$98<>""),Fits!$B$98,NA()) -> #N/A | DP6: =IF($AS6="",NA(),$AS6) -> #N/A | DQ6: =IF(AND($D6="Drift",$AS6="",$X6<>""),$X6,NA()) -> #N/A | DR6: =IF(AND($D6="Drift",$Z6<>""),$Z6,NA()) -> #N/A | DS6: =IF(AND(OR($D6="Sample",$D6="Check"),$AA6<>""),$AA6,NA()) -> #N/A | DT6: =IF(OR($B6="",Fits!$B$138=""),NA(),Fits!$B$138) -> 1.76 | DU6: =IF(OR($B6="",Fits!$B$139=""),NA(),Fits!$B$139) -> 20.68 | DV6: =IF($BT6="",NA(),$BT6) -> -1.217 | DW6: =IF($AP6="",NA(),$AO6) -> #N/A | DX6: =IF($AP6="",NA(),$AP6) -> #N/A | DY6: =IF(AND($D6="Sample",$P6<>""),$P6,NA()) -> #N/A | DZ6: =IF(AND($D6="Sample",$P6<>"",Fits!$B$105<>""),Fits!$B$105,NA()) -> #N/A | EA6: =IF($AT6="",NA(),$AT6) -> #N/A | EB6: =IF(AND($D6="Drift",$AT6="",$AC6<>""),$AC6,NA()) -> #N/A | EC6: =IF(AND($D6="Drift",$AE6<>""),$AE6,NA()) -> #N/A | ED6: =IF(AND(OR($D6="Sample",$D6="Check"),$AF6<>""),$AF6,NA()) -> #N/A | EE6: =IF(OR($B6="",Fits!$B$158=""),NA(),Fits!$B$158) -> -40.81 | EF6: =IF(OR($B6="",Fits!$B$159=""),NA(),Fits!$B$159) -> -20.29 | EG6: =IF($BW6="",NA(),$BW6) -> -25.736 | EH6: =IF(AND($EN6=1,ISNUMBER($N6)),$N6,NA()) -> #N/A | EI6: =IF($B6="","",$A6) -> 1 | EJ6: =IF(OR(AND(ISNUMBER($L6),Fits!$B$97>0,$L6>Fits!$B$97),AND(ISNUMBER($P6),Fits!$B$104>0,$P6>Fits!$B$104)),1,0) -> 0 | EK6: 0 | EL6: =IF(AND($EK6=0,ISNUMBER($N6)),$N6,"") -> 38.6 | EM6: =IF(AND($EK6=1,ISNUMBER($N6),ISNUMBER($EL6)),$N6-$EL6,"") | EN6: =IF(Setup!$B$28="",0,IF(ISNUMBER($EM6),IF($EM6>Setup!$B$28,1,0),0)) -> 0 | EO6: =IF($EN6=1,COUNTIF($EN$6:$EN6,1),"") | EP6: 0 | EQ6: =IF(ISNUMBER($BI6),IF(COUNT($BI$6:$BI6)<=5,$BI6,""),"") -> 34.2 | ER6: =IF(OR(NOT(ISNUMBER($BJ6)),$EK6=1),"",IF($BJ6<=Setup!$B$26,$A6,""))
A7: 2 | B7: =IFERROR(INDEX(Raw!$B$2:$B$1001,MATCH($A7,Raw!$A$2:$A$1001,0)),"") -> Ace Bypass | C7: =IF($B7="","",MAX($CS7:$DE7)) -> 44 | D7: =IF($B7="","",IF($C7=0,"Sample",INDEX(Setup!$B$37:$B$49,$C7-36))) -> Exclude | E7: =IF($B7="","",IFERROR(IF(INDEX(Raw!$E$2:$E$1001,MATCH($A7,Raw!$A$2:$A$1001,0))=0,"",INDEX(Raw!$E$2:$E$1001,MATCH($A7,Raw!$A$2:$A$1001,0))),"")) -> 1.131 | G7: =IF($B7="","",IF($F7<>"",$F7,IF($E7="","",$E7))) -> 1.131 | H7: =IF($B7="","",SUMPRODUCT(MAX((Raw!$A$2:$A$1001=$A7)*(Raw!$R$2:$R$1001="N")*Raw!$D$2:$D$1001))) -> 3 | I7: =IF(OR($H7="",$H7=0),"",$A7&"|N|"&$H7) -> 2|N|3 | J7: =IF($B7="","",SUMPRODUCT(MIN((Raw!$A$2:$A$1001=$A7)*(Raw!$R$2:$R$1001="C")*Raw!$D$2:$D$1001+(1-(Raw!$A$2:$A$1001=$A7)*(Raw!$R$2:$R$1001="C"))*9999))) -> 4 | K7: =IF(OR($J7="",$J7=0,$J7=9999),"",$A7&"|C|"&$J7) -> 2|C|4 | L7: =IF($I7="","",IF(INDEX(Raw!$I$2:$I$1001,MATCH($I7,Raw!$S$2:$S$1001,0))<>0,"",INDEX(Raw!$H$2:$H$1001,MATCH($I7,Raw!$S$2:$S$1001,0)))) -> 79.936 | M7: =IF($I7="","",IF(INDEX(Raw!$I$2:$I$1001,MATCH($I7,Raw!$S$2:$S$1001,0))<>0,"",INDEX(Raw!$F$2:$F$1001,MATCH($I7,Raw!$S$2:$S$1001,0)))) -> 4689 | N7: =IF($I7="","",IF(INDEX(Raw!$I$2:$I$1001,MATCH($I7,Raw!$S$2:$S$1001,0))<>0,"",INDEX(Raw!$G$2:$G$1001,MATCH($I7,Raw!$S$2:$S$1001,0)))) -> 37.2 | O7: =IF($I7="","",IF(INDEX(Raw!$I$2:$I$1001,MATCH($I7,Raw!$S$2:$S$1001,0))<>0,"",INDEX(Raw!$N$2:$N$1001,MATCH($I7,Raw!$S$2:$S$1001,0)))) -> -4.989 | P7: =IF($K7="","",IF(INDEX(Raw!$I$2:$I$1001,MATCH($K7,Raw!$S$2:$S$1001,0))<>0,"",INDEX(Raw!$K$2:$K$1001,MATCH($K7,Raw!$S$2:$S$1001,0)))) -> 362.648 | Q7: =IF($K7="","",IF(INDEX(Raw!$I$2:$I$1001,MATCH($K7,Raw!$S$2:$S$1001,0))<>0,"",INDEX(Raw!$J$2:$J$1001,MATCH($K7,Raw!$S$2:$S$1001,0)))) -> 14212 | R7: =IF($K7="","",IF(INDEX(Raw!$I$2:$I$1001,MATCH($K7,Raw!$S$2:$S$1001,0))<>0,"",INDEX(Raw!$O$2:$O$1001,MATCH($K7,Raw!$S$2:$S$1001,0)))) -> -9.107 | S7: =IF($B7="","",IF($C7=0,"",IF(INDEX(Setup!$D$37:$D$49,$C7-36)="","",INDEX(Setup!$D$37:$D$49,$C7-36)))) | T7: =IF($B7="","",IF($C7=0,"",IF(INDEX(Setup!$C$37:$C$49,$C7-36)="","",INDEX(Setup!$C$37:$C$49,$C7-36)))) | U7: =IF($B7="","",IF($C7=0,"",IF(INDEX(Setup!$F$37:$F$49,$C7-36)="","",INDEX(Setup!$F$37:$F$49,$C7-36)))) -> 10.36 | V7: =IF($B7="","",IF($C7=0,"",IF(INDEX(Setup!$E$37:$E$49,$C7-36)="","",INDEX(Setup!$E$37:$E$49,$C7-36)))) -> 71.09 | W7: =IF($O7="","",IF(OR(Fits!$C$5<>"Yes",$D7="Blank",$L7<=Fits!$B$6),$O7,($L7*$O7-Fits!$B$6*Fits!$B$7)/($L7-Fits!$B$6))) -> -4.989 | X7: =IF($W7="","",$W7-Fits!$B$20*($L7-Fits!$B$16)) -> -4.989 | Y7: =IF($W7="","",IF(OR(Fits!$B$38="Row",$BI7=""),$A7,$BI7)) -> 2 | Z7: =IF($X7="","",$X7-Fits!$B$39*($Y7-Fits!$B$40)) -> -5.4577343 | AA7: =IF(OR($Z7="",Fits!$B$55<2),"",Fits!$B$56*$Z7+Fits!$B$57) -> -4.5756287 | AB7: =IF($R7="","",IF(OR(Fits!$C$9<>"Yes",$D7="Blank",$P7<=Fits!$B$10),$R7,($P7*$R7-Fits!$B$10*Fits!$B$11)/($P7-Fits!$B$10))) -> -9.107 | AC7: =IF($AB7="","",$AB7-Fits!$B$28*($P7-Fits!$B$24)) -> -9.5143429 | AD7: =IF($AB7="","",IF(OR(Fits!$B$50="Row",$BI7=""),$A7,$BI7)) -> 2 | AE7: =IF($AC7="","",$AC7-Fits!$B$51*($AD7-Fits!$B$52)) -> -9.431817 | AF7: =IF(OR($AE7="",Fits!$B$62<2),"",Fits!$B$63*$AE7+Fits!$B$64) -> -26.557524 | AG7: =IF(OR($L7="",Fits!$B$69<3),"",($L7-Fits!$B$71)/Fits!$B$70) -> 128.76813 | AH7: =IF(OR($P7="",Fits!$B$75<3),"",($P7-Fits!$B$77)/Fits!$B$76) -> 822.00546 | AI7: =IF(OR($AG7="",$G7="",$G7=0),"",$AG7/($G7*1000)*100) -> 11.385334 | AJ7: =IF(OR($AH7="",$G7="",$G7=0),"",$AH7/($G7*1000)*100) -> 72.679527 | AK7: =IF(OR($AG7="",$AH7="",$AG7<=0),"",($AH7/Setup!$B$52)/($AG7/Setup!$B$53)) -> 7.444444 | AL7: =IF(OR($AG7="",$AH7="",$AG7<=0),"",$AH7/$AG7) -> 6.3836094 | AM7: =IF($D7="Linearity",IF($L7="","",$L7),"") | AN7: =IF($D7="Linearity",IF($W7="","",$W7),"") | AO7: =IF($D7="Linearity",IF($P7="","",$P7),"") | AP7: =IF($D7="Linearity",IF($AB7="","",$AB7),"") | AQ7: =IF($D7="Drift",IF($A7<IF(Setup!$B$14="",0,Setup!$B$14),"",$A7),"") | AR7: =IF($D7="Drift",IF($A7<IF(Setup!$B$14="",0,Setup!$B$14),"",IF($BI7="","",$BI7)),"") | AS7: =IF($D7="Drift",IF($A7<IF(Setup!$B$14="",0,Setup!$B$14),"",IF(OR($X7="",$BX7=1),"",$X7)),"") | AT7: =IF($D7="Drift",IF($A7<IF(Setup!$B$14="",0,Setup!$B$14),"",IF(OR($AC7="",$BY7=1),"",$AC7)),"") | AU7: =IF($D7="Anchor",IF(OR($Z7="",$S7=""),"",$Z7),"") | AV7: =IF($D7="Anchor",IF(OR($Z7="",$S7=""),"",$S7),"") | AW7: =IF($D7="Anchor",IF(OR($AE7="",$T7=""),"",$AE7),"") | AX7: =IF($D7="Anchor",IF(OR($AE7="",$T7=""),"",$T7),"") | AY7: =IF(OR($D7="Blank",$D7="Exclude",$D7="Sample",$D7="",$G7="",$U7="",$L7=""),"",$G7*1000*$U7/100) | AZ7: =IF($AY7="","",$L7) | BA7: =IF(OR($D7="Blank",$D7="Exclude",$D7="Sample",$D7="",$G7="",$V7="",$P7=""),"",$G7*1000*$V7/100) | BB7: =IF($BA7="","",$P7) | BC7: =IF(AND($D7="Blank",$L7<>""),$O7,"") | BD7: =IF($BC7="","",$L7) | BE7: =IF(AND($D7="Blank",$P7<>""),$R7,"") | BF7: =IF($BE7="","",$P7) | BG7: =IF(AND($D7="Drift",$BX7<>1),IF($AA7="","",$AA7),"") | BH7: =IF(AND($D7="Drift",$BY7<>1),IF($AF7="","",$AF7),"") | BI7: =IF($B7="","",IFERROR(INDEX(Raw!$G$2:$G$1001,MATCH($A7&"|N|"&SUMPRODUCT(MAX((Raw!$A$2:$A$1001=$A7)*(Raw!$R$2:$R$1001="N")*(Raw!$I$2:$I$1001=1)*Raw!$D$2:$D$1001)),Raw!$S$2:$S$1001,0)),"")) -> 33.2 | BJ7: =IF(OR($BI7="",Fits!$B$85<=0),"",($BI7-Fits!$B$83)/Fits!$B$85) -> 0.90990991 | BK7: =IF($AS7="","",IF($A7>=Fits!$B$86,"",$A7)) | BL7: =IF($BK7="","",$X7) | BM7: =IF($AS7="","",IF($A7<Fits!$B$86,"",$A7)) | BN7: =IF($BM7="","",$X7) | BO7: =IF(AND($D7="Drift",$BX7<>1),IF($O7="","",$O7),"") | BP7: =IF(AND($D7="Drift",$BX7<>1),IF($W7="","",$W7),"") | BQ7: =IF(AND($D7="Drift",$BX7<>1),IF($X7="","",$X7),"") | BR7: =IF(AND($D7="Drift",$BX7<>1),IF($Z7="","",$Z7),"") | BS7: =IF(OR($B7="",$H7=""),"",SUMPRODUCT(MIN((Raw!$A$2:$A$1001=$A7)*(Raw!$R$2:$R$1001="N")*(Raw!$I$2:$I$1001=0)*(Raw!$D$2:$D$1001<$H7)*Raw!$D$2:$D$1001+(1-(Raw!$A$2:$A$1001=$A7)*(Raw!$R$2:$R$1001="N")*(Raw!$I$2:$I$1001=0)*(Raw!$D$2:$D$1001<$H7))*9999))) -> 1 | BT7: =IF(OR($BS7="",$BS7=9999,$BS7=0),"",IFERROR(INDEX(Raw!$N$2:$N$1001,MATCH($A7&"|N|"&$BS7,Raw!$S$2:$S$1001,0)),"")) -> -1.139 | BU7: =IF($B7="","",SUMPRODUCT(MIN((Raw!$A$2:$A$1001=$A7)*(Raw!$R$2:$R$1001="C")*(Raw!$I$2:$I$1001=1)*Raw!$D$2:$D$1001+(1-(Raw!$A$2:$A$1001=$A7)*(Raw!$R$2:$R$1001="C")*(Raw!$I$2:$I$1001=1))*9999))) -> 5 | BV7: =IF(OR($BU7="",$BU7=9999),"",SUMPRODUCT(MIN((Raw!$A$2:$A$1001=$A7)*(Raw!$R$2:$R$1001="C")*(Raw!$I$2:$I$1001=0)*(Raw!$D$2:$D$1001>$BU7)*Raw!$D$2:$D$1001+(1-(Raw!$A$2:$A$1001=$A7)*(Raw!$R$2:$R$1001="C")*(Raw!$I$2:$I$1001=0)*(Raw!$D$2:$D$1001>$BU7))*9999))) -> 6 | BW7: =IF(OR($BV7="",$BV7=9999,$BV7=0),"",IFERROR(INDEX(Raw!$O$2:$O$1001,MATCH($A7&"|C|"&$BV7,Raw!$S$2:$S$1001,0)),"")) -> -25.353 | BX7: =IF($B7="","",IF(ISNUMBER(SEARCH(","&$A7&",",","&SUBSTITUTE(Setup!$B$16," ","")&",")),1,0)) -> 0 | BY7: =IF($B7="","",IF(ISNUMBER(SEARCH(","&$A7&",",","&SUBSTITUTE(Setup!$B$17," ","")&",")),1,0)) -> 0 | BZ7: =IF($AS7="","",IF(Fits!$B$38="Row",$AQ7,IF($AR7="","",$AR7))) | CA7: =IF($AT7="","",IF(Fits!$B$50="Row",$AQ7,IF($AR7="","",$AR7))) | CB7: =IF(OR($D7<>"Drift",$X7="",$A7<IF(Setup!$B$14="",0,Setup!$B$14),Fits!$B$107<3,Fits!$B$110="",Fits!$B$109=0,IF(Fits!$B$38="Row",$AQ7,$AR7)=""),"",IF($BX7=1,IF(OR(Fits!$B$111="",Fits!$B$111=0),"",($X7-(IF(Fits!$B$38="Row",Fits!$B$32,Fits!$B$35)*IF(Fits!$B$38="Row",$AQ7,$AR7)+Fits!$B$110))/(Fits!$B$111*SQRT(1+(1/Fits!$B$107+(IF(Fits!$B$38="Row",$AQ7,$AR7)-Fits!$B$108)^2/Fits!$B$109)))),IF(OR(Fits!$B$107<4,(1/Fits!$B$107+(IF(Fits!$B$38="Row",$AQ7,$AR7)-Fits!$B$108)^2/Fits!$B$109)>=1),"",IF((Fits!$B$116-($X7-(IF(Fits!$B$38="Row",Fits!$B$32,Fits!$B$35)*IF(Fits!$B$38="Row",$AQ7,$AR7)+Fits!$B$110))^2/(1-(1/Fits!$B$107+(IF(Fits!$B$38="Row",$AQ7,$AR7)-Fits!$B$108)^2/Fits!$B$109)))<=0,"",($X7-(IF(Fits!$B$38="Row",Fits!$B$32,Fits!$B$35)*IF(Fits!$B$38="Row",$AQ7,$AR7)+Fits!$B$110))/(SQRT((Fits!$B$116-($X7-(IF(Fits!$B$38="Row",Fits!$B$32,Fits!$B$35)*IF(Fits!$B$38="Row",$AQ7,$AR7)+Fits!$B$110))^2/(1-(1/Fits!$B$107+(IF(Fits!$B$38="Row",$AQ7,$AR7)-Fits!$B$108)^2/Fits!$B$109)))/(Fits!$B$107-3))*SQRT(1-(1/Fits!$B$107+(IF(Fits!$B$38="Row",$AQ7,$AR7)-Fits!$B$108)^2/Fits!$B$109))))))) | CC7: =IF(OR($D7<>"Drift",$AC7="",$A7<IF(Setup!$B$14="",0,Setup!$B$14),Fits!$B$120<3,Fits!$B$123="",Fits!$B$122=0,IF(Fits!$B$50="Row",$AQ7,$AR7)=""),"",IF($BY7=1,IF(OR(Fits!$B$124="",Fits!$B$124=0),"",($AC7-(IF(Fits!$B$50="Row",Fits!$B$44,Fits!$B$47)*IF(Fits!$B$50="Row",$AQ7,$AR7)+Fits!$B$123))/(Fits!$B$124*SQRT(1+(1/Fits!$B$120+(IF(Fits!$B$50="Row",$AQ7,$AR7)-Fits!$B$121)^2/Fits!$B$122)))),IF(OR(Fits!$B$120<4,(1/Fits!$B$120+(IF(Fits!$B$50="Row",$AQ7,$AR7)-Fits!$B$121)^2/Fits!$B$122)>=1),"",IF((Fits!$B$129-($AC7-(IF(Fits!$B$50="Row",Fits!$B$44,Fits!$B$47)*IF(Fits!$B$50="Row",$AQ7,$AR7)+Fits!$B$123))^2/(1-(1/Fits!$B$120+(IF(Fits!$B$50="Row",$AQ7,$AR7)-Fits!$B$121)^2/Fits!$B$122)))<=0,"",($AC7-(IF(Fits!$B$50="Row",Fits!$B$44,Fits!$B$47)*IF(Fits!$B$50="Row",$AQ7,$AR7)+Fits!$B$123))/(SQRT((Fits!$B$129-($AC7-(IF(Fits!$B$50="Row",Fits!$B$44,Fits!$B$47)*IF(Fits!$B$50="Row",$AQ7,$AR7)+Fits!$B$123))^2/(1-(1/Fits!$B$120+(IF(Fits!$B$50="Row",$AQ7,$AR7)-Fits!$B$121)^2/Fits!$B$122)))/(Fits!$B$120-3))*SQRT(1-(1/Fits!$B$120+(IF(Fits!$B$50="Row",$AQ7,$AR7)-Fits!$B$121)^2/Fits!$B$122))))))) | CD7: =IF($AU7="","",1) | CE7: =IF($AU7="","",$AU7-Fits!$B$133) | CF7: =IF($AU7="","",($AV7-(Fits!$B$56*$AU7+Fits!$B$57))-Fits!$B$56*($AU7-Fits!$B$133)) | CG7: =IF($AU7="","",$AU7^2) | CH7: =IF($AW7="","",1) | CI7: =IF($AW7="","",$AW7-Fits!$B$153) | CJ7: =IF($AW7="","",($AX7-(Fits!$B$63*$AW7+Fits!$B$64))-Fits!$B$63*($AW7-Fits!$B$153)) | CK7: =IF($AW7="","",$AW7^2) | CL7: =IF(OR($Z7="",Fits!$B$55<3,Fits!$B$133="",Fits!$B$134="",Fits!$B$134=0,Fits!$B$136=""),"",SQRT((Fits!$B$136*Fits!$B$56)^2+SUMPRODUCT((Fits!$J$163:$J$175*(Fits!$B$163:$B$175/Fits!$B$55+Fits!$H$163:$H$175*($Z7-Fits!$B$133)/Fits!$B$134))^2)+SUMPRODUCT((Fits!$G$163:$G$175*(($Z7-Fits!$B$133)*Fits!$I$163:$I$175/Fits!$B$134-Fits!$B$163:$B$175*Fits!$B$56/Fits!$B$55))^2))) -> 0.25209391 | CM7: =IF($CL7="","",Setup!$B$32*$CL7) -> 0.50418781 | CN7: =IF(OR($AE7="",Fits!$B$62<3,Fits!$B$153="",Fits!$B$154="",Fits!$B$154=0,Fits!$B$156=""),"",SQRT((Fits!$B$156*Fits!$B$63)^2+SUMPRODUCT((Fits!$J$183:$J$195*(Fits!$B$183:$B$195/Fits!$B$62+Fits!$H$183:$H$195*($AE7-Fits!$B$153)/Fits!$B$154))^2)+SUMPRODUCT((Fits!$G$183:$G$195*(($AE7-Fits!$B$153)*Fits!$I$183:$I$195/Fits!$B$154-Fits!$B$183:$B$195*Fits!$B$63/Fits!$B$62))^2))) -> 0.037930234 | CO7: =IF($CN7="","",Setup!$B$32*$CN7) -> 0.075860468 | CP7: =IF(OR(NOT(ISNUMBER($BJ7)),$EK7=1),$CP6,IF($BJ7<=Setup!$B$26,$CP6+1,0)) -> 0 | CQ7: =IF($BT7="","",$A7) -> 2 | CR7: =IF($BW7="","",$A7) -> 2 | CS7: =IF($B7="","",IF(Setup!$A$37="",0,IF(ISNUMBER(SEARCH(Setup!$A$37,$B7)),37,0))) -> 0 | CT7: =IF($B7="","",IF(Setup!$A$38="",0,IF(ISNUMBER(SEARCH(Setup!$A$38,$B7)),38,0))) -> 0 | CU7: =IF($B7="","",IF(Setup!$A$39="",0,IF(ISNUMBER(SEARCH(Setup!$A$39,$B7)),39,0))) -> 0 | CV7: =IF($B7="","",IF(Setup!$A$40="",0,IF(ISNUMBER(SEARCH(Setup!$A$40,$B7)),40,0))) -> 0 | CW7: =IF($B7="","",IF(Setup!$A$41="",0,IF(ISNUMBER(SEARCH(Setup!$A$41,$B7)),41,0))) -> 0 | CX7: =IF($B7="","",IF(Setup!$A$42="",0,IF(ISNUMBER(SEARCH(Setup!$A$42,$B7)),42,0))) -> 0 | CY7: =IF($B7="","",IF(Setup!$A$43="",0,IF(ISNUMBER(SEARCH(Setup!$A$43,$B7)),43,0))) -> 0 | CZ7: =IF($B7="","",IF(Setup!$A$44="",0,IF(ISNUMBER(SEARCH(Setup!$A$44,$B7)),44,0))) -> 44 | DA7: =IF($B7="","",IF(Setup!$A$45="",0,IF(ISNUMBER(SEARCH(Setup!$A$45,$B7)),45,0))) -> 0 | DB7: =IF($B7="","",IF(Setup!$A$46="",0,IF(ISNUMBER(SEARCH(Setup!$A$46,$B7)),46,0))) -> 0 | DC7: =IF($B7="","",IF(Setup!$A$47="",0,IF(ISNUMBER(SEARCH(Setup!$A$47,$B7)),47,0))) -> 0 | DD7: =IF($B7="","",IF(Setup!$A$48="",0,IF(ISNUMBER(SEARCH(Setup!$A$48,$B7)),48,0))) -> 0 | DE7: =IF($B7="","",IF(Setup!$A$49="",0,IF(ISNUMBER(SEARCH(Setup!$A$49,$B7)),49,0))) -> 0 | DF7: =IF($B7="",NA(),$A7) -> 2 | DG7: =IF($BI7="",NA(),$BI7) -> 33.2 | DH7: =IF($N7="",NA(),$N7) -> 37.2 | DI7: =IF(AND($D7="Drift",$N7<>""),$N7,NA()) -> #N/A | DJ7: =IF(AND($D7="Drift",$N7<>""),$N7,"") | DK7: =IF($DJ7="","",$A7) | DL7: =IF($AN7="",NA(),$AM7) -> #N/A | DM7: =IF($AN7="",NA(),$AN7) -> #N/A | DN7: =IF(AND($D7="Sample",$L7<>""),$L7,NA()) -> #N/A | DO7: =IF(AND($D7="Sample",$L7<>"",Fits!$B$98<>""),Fits!$B$98,NA()) -> #N/A | DP7: =IF($AS7="",NA(),$AS7) -> #N/A | DQ7: =IF(AND($D7="Drift",$AS7="",$X7<>""),$X7,NA()) -> #N/A | DR7: =IF(AND($D7="Drift",$Z7<>""),$Z7,NA()) -> #N/A | DS7: =IF(AND(OR($D7="Sample",$D7="Check"),$AA7<>""),$AA7,NA()) -> #N/A | DT7: =IF(OR($B7="",Fits!$B$138=""),NA(),Fits!$B$138) -> 1.76 | DU7: =IF(OR($B7="",Fits!$B$139=""),NA(),Fits!$B$139) -> 20.68 | DV7: =IF($BT7="",NA(),$BT7) -> -1.139 | DW7: =IF($AP7="",NA(),$AO7) -> #N/A | DX7: =IF($AP7="",NA(),$AP7) -> #N/A | DY7: =IF(AND($D7="Sample",$P7<>""),$P7,NA()) -> #N/A | DZ7: =IF(AND($D7="Sample",$P7<>"",Fits!$B$105<>""),Fits!$B$105,NA()) -> #N/A | EA7: =IF($AT7="",NA(),$AT7) -> #N/A | EB7: =IF(AND($D7="Drift",$AT7="",$AC7<>""),$AC7,NA()) -> #N/A | EC7: =IF(AND($D7="Drift",$AE7<>""),$AE7,NA()) -> #N/A | ED7: =IF(AND(OR($D7="Sample",$D7="Check"),$AF7<>""),$AF7,NA()) -> #N/A | EE7: =IF(OR($B7="",Fits!$B$158=""),NA(),Fits!$B$158) -> -40.81 | EF7: =IF(OR($B7="",Fits!$B$159=""),NA(),Fits!$B$159) -> -20.29 | EG7: =IF($BW7="",NA(),$BW7) -> -25.353 | EH7: =IF(AND($EN7=1,ISNUMBER($N7)),$N7,NA()) -> #N/A | EI7: =IF($B7="","",$A7) -> 2 | EJ7: =IF(OR(AND(ISNUMBER($L7),Fits!$B$97>0,$L7>Fits!$B$97),AND(ISNUMBER($P7),Fits!$B$104>0,$P7>Fits!$B$104)),1,0) -> 1 | EK7: =IF($EJ6=1,1,0) -> 0 | EL7: =IF(AND($EK7=0,ISNUMBER($N7)),$N7,$EL6) -> 37.2 | EM7: =IF(AND($EK7=1,ISNUMBER($N7),ISNUMBER($EL7)),$N7-$EL7,"") | EN7: =IF(Setup!$B$28="",0,IF(ISNUMBER($EM7),IF($EM7>Setup!$B$28,1,0),0)) -> 0 | EO7: =IF($EN7=1,COUNTIF($EN$6:$EN7,1),"") | EP7: =IF(AND($EJ6=1,OR($D7="Sample",$D7="Check")),1,0) -> 0 | EQ7: =IF(ISNUMBER($BI7),IF(COUNT($BI$6:$BI7)<=5,$BI7,""),"") -> 33.2 | ER7: =IF(OR(NOT(ISNUMBER($BJ7)),$EK7=1),$ER6,IF($BJ7<=Setup!$B$26,IF($CP6=0,$A7,$ER6),""))
A8: 3 | B8: =IFERROR(INDEX(Raw!$B$2:$B$1001,MATCH($A8,Raw!$A$2:$A$1001,0)),"") -> Ace Bypass | C8: =IF($B8="","",MAX($CS8:$DE8)) -> 44 | D8: =IF($B8="","",IF($C8=0,"Sample",INDEX(Setup!$B$37:$B$49,$C8-36))) -> Exclude | E8: =IF($B8="","",IFERROR(IF(INDEX(Raw!$E$2:$E$1001,MATCH($A8,Raw!$A$2:$A$1001,0))=0,"",INDEX(Raw!$E$2:$E$1001,MATCH($A8,Raw!$A$2:$A$1001,0))),"")) -> 0.49 | G8: =IF($B8="","",IF($F8<>"",$F8,IF($E8="","",$E8))) -> 0.49 | H8: =IF($B8="","",SUMPRODUCT(MAX((Raw!$A$2:$A$1001=$A8)*(Raw!$R$2:$R$1001="N")*Raw!$D$2:$D$1001))) -> 3 | I8: =IF(OR($H8="",$H8=0),"",$A8&"|N|"&$H8) -> 3|N|3 | J8: =IF($B8="","",SUMPRODUCT(MIN((Raw!$A$2:$A$1001=$A8)*(Raw!$R$2:$R$1001="C")*Raw!$D$2:$D$1001+(1-(Raw!$A$2:$A$1001=$A8)*(Raw!$R$2:$R$1001="C"))*9999))) -> 4 | K8: =IF(OR($J8="",$J8=0,$J8=9999),"",$A8&"|C|"&$J8) -> 3|C|4 | L8: =IF($I8="","",IF(INDEX(Raw!$I$2:$I$1001,MATCH($I8,Raw!$S$2:$S$1001,0))<>0,"",INDEX(Raw!$H$2:$H$1001,MATCH($I8,Raw!$S$2:$S$1001,0)))) -> 34.829 | M8: =IF($I8="","",IF(INDEX(Raw!$I$2:$I$1001,MATCH($I8,Raw!$S$2:$S$1001,0))<>0,"",INDEX(Raw!$F$2:$F$1001,MATCH($I8,Raw!$S$2:$S$1001,0)))) -> 1952 | N8: =IF($I8="","",IF(INDEX(Raw!$I$2:$I$1001,MATCH($I8,Raw!$S$2:$S$1001,0))<>0,"",INDEX(Raw!$G$2:$G$1001,MATCH($I8,Raw!$S$2:$S$1001,0)))) -> 36.4 | O8: =IF($I8="","",IF(INDEX(Raw!$I$2:$I$1001,MATCH($I8,Raw!$S$2:$S$1001,0))<>0,"",INDEX(Raw!$N$2:$N$1001,MATCH($I8,Raw!$S$2:$S$1001,0)))) -> -4.515 | P8: =IF($K8="","",IF(INDEX(Raw!$I$2:$I$1001,MATCH($K8,Raw!$S$2:$S$1001,0))<>0,"",INDEX(Raw!$K$2:$K$1001,MATCH($K8,Raw!$S$2:$S$1001,0)))) -> 155.895 | Q8: =IF($K8="","",IF(INDEX(Raw!$I$2:$I$1001,MATCH($K8,Raw!$S$2:$S$1001,0))<>0,"",INDEX(Raw!$J$2:$J$1001,MATCH($K8,Raw!$S$2:$S$1001,0)))) -> 6715 | R8: =IF($K8="","",IF(INDEX(Raw!$I$2:$I$1001,MATCH($K8,Raw!$S$2:$S$1001,0))<>0,"",INDEX(Raw!$O$2:$O$1001,MATCH($K8,Raw!$S$2:$S$1001,0)))) -> -9.45 | S8: =IF($B8="","",IF($C8=0,"",IF(INDEX(Setup!$D$37:$D$49,$C8-36)="","",INDEX(Setup!$D$37:$D$49,$C8-36)))) | T8: =IF($B8="","",IF($C8=0,"",IF(INDEX(Setup!$C$37:$C$49,$C8-36)="","",INDEX(Setup!$C$37:$C$49,$C8-36)))) | U8: =IF($B8="","",IF($C8=0,"",IF(INDEX(Setup!$F$37:$F$49,$C8-36)="","",INDEX(Setup!$F$37:$F$49,$C8-36)))) -> 10.36 | V8: =IF($B8="","",IF($C8=0,"",IF(INDEX(Setup!$E$37:$E$49,$C8-36)="","",INDEX(Setup!$E$37:$E$49,$C8-36)))) -> 71.09 | W8: =IF($O8="","",IF(OR(Fits!$C$5<>"Yes",$D8="Blank",$L8<=Fits!$B$6),$O8,($L8*$O8-Fits!$B$6*Fits!$B$7)/($L8-Fits!$B$6))) -> -4.515 | X8: =IF($W8="","",$W8-Fits!$B$20*($L8-Fits!$B$16)) -> -4.515 | Y8: =IF($W8="","",IF(OR(Fits!$B$38="Row",$BI8=""),$A8,$BI8)) -> 3 | Z8: =IF($X8="","",$X8-Fits!$B$39*($Y8-Fits!$B$40)) -> -4.96898 | AA8: =IF(OR($Z8="",Fits!$B$55<2),"",Fits!$B$56*$Z8+Fits!$B$57) -> -4.0738745 | AB8: =IF($R8="","",IF(OR(Fits!$C$9<>"Yes",$D8="Blank",$P8<=Fits!$B$10),$R8,($P8*$R8-Fits!$B$10*Fits!$B$11)/($P8-Fits!$B$10))) -> -9.45 | AC8: =IF($AB8="","",$AB8-Fits!$B$28*($P8-Fits!$B$24)) -> -9.4990914 | AD8: =IF($AB8="","",IF(OR(Fits!$B$50="Row",$BI8=""),$A8,$BI8)) -> 3 | AE8: =IF($AC8="","",$AC8-Fits!$B$51*($AD8-Fits!$B$52)) -> -9.4191632 | AF8: =IF(OR($AE8="",Fits!$B$62<2),"",Fits!$B$63*$AE8+Fits!$B$64) -> -26.544691 | AG8: =IF(OR($L8="",Fits!$B$69<3),"",($L8-Fits!$B$71)/Fits!$B$70) -> 54.255501 | AH8: =IF(OR($P8="",Fits!$B$75<3),"",($P8-Fits!$B$77)/Fits!$B$76) -> 351.09371 | AI8: =IF(OR($AG8="",$G8="",$G8=0),"",$AG8/($G8*1000)*100) -> 11.072551 | AJ8: =IF(OR($AH8="",$G8="",$G8=0),"",$AH8/($G8*1000)*100) -> 71.651778 | AK8: =IF(OR($AG8="",$AH8="",$AG8<=0),"",($AH8/Setup!$B$52)/($AG8/Setup!$B$53)) -> 7.5464941 | AL8: =IF(OR($AG8="",$AH8="",$AG8<=0),"",$AH8/$AG8) -> 6.4711173 | AM8: =IF($D8="Linearity",IF($L8="","",$L8),"") | AN8: =IF($D8="Linearity",IF($W8="","",$W8),"") | AO8: =IF($D8="Linearity",IF($P8="","",$P8),"") | AP8: =IF($D8="Linearity",IF($AB8="","",$AB8),"") | AQ8: =IF($D8="Drift",IF($A8<IF(Setup!$B$14="",0,Setup!$B$14),"",$A8),"") | AR8: =IF($D8="Drift",IF($A8<IF(Setup!$B$14="",0,Setup!$B$14),"",IF($BI8="","",$BI8)),"") | AS8: =IF($D8="Drift",IF($A8<IF(Setup!$B$14="",0,Setup!$B$14),"",IF(OR($X8="",$BX8=1),"",$X8)),"") | AT8: =IF($D8="Drift",IF($A8<IF(Setup!$B$14="",0,Setup!$B$14),"",IF(OR($AC8="",$BY8=1),"",$AC8)),"") | AU8: =IF($D8="Anchor",IF(OR($Z8="",$S8=""),"",$Z8),"") | AV8: =IF($D8="Anchor",IF(OR($Z8="",$S8=""),"",$S8),"") | AW8: =IF($D8="Anchor",IF(OR($AE8="",$T8=""),"",$AE8),"") | AX8: =IF($D8="Anchor",IF(OR($AE8="",$T8=""),"",$T8),"") | AY8: =IF(OR($D8="Blank",$D8="Exclude",$D8="Sample",$D8="",$G8="",$U8="",$L8=""),"",$G8*1000*$U8/100) | AZ8: =IF($AY8="","",$L8) | BA8: =IF(OR($D8="Blank",$D8="Exclude",$D8="Sample",$D8="",$G8="",$V8="",$P8=""),"",$G8*1000*$V8/100) | BB8: =IF($BA8="","",$P8) | BC8: =IF(AND($D8="Blank",$L8<>""),$O8,"") | BD8: =IF($BC8="","",$L8) | BE8: =IF(AND($D8="Blank",$P8<>""),$R8,"") | BF8: =IF($BE8="","",$P8) | BG8: =IF(AND($D8="Drift",$BX8<>1),IF($AA8="","",$AA8),"") | BH8: =IF(AND($D8="Drift",$BY8<>1),IF($AF8="","",$AF8),"") | BI8: =IF($B8="","",IFERROR(INDEX(Raw!$G$2:$G$1001,MATCH($A8&"|N|"&SUMPRODUCT(MAX((Raw!$A$2:$A$1001=$A8)*(Raw!$R$2:$R$1001="N")*(Raw!$I$2:$I$1001=1)*Raw!$D$2:$D$1001)),Raw!$S$2:$S$1001,0)),"")) -> 32.7 | BJ8: =IF(OR($BI8="",Fits!$B$85<=0),"",($BI8-Fits!$B$83)/Fits!$B$85) -> 0.86486486 | BK8: =IF($AS8="","",IF($A8>=Fits!$B$86,"",$A8)) | BL8: =IF($BK8="","",$X8) | BM8: =IF($AS8="","",IF($A8<Fits!$B$86,"",$A8)) | BN8: =IF($BM8="","",$X8) | BO8: =IF(AND($D8="Drift",$BX8<>1),IF($O8="","",$O8),"") | BP8: =IF(AND($D8="Drift",$BX8<>1),IF($W8="","",$W8),"") | BQ8: =IF(AND($D8="Drift",$BX8<>1),IF($X8="","",$X8),"") | BR8: =IF(AND($D8="Drift",$BX8<>1),IF($Z8="","",$Z8),"") | BS8: =IF(OR($B8="",$H8=""),"",SUMPRODUCT(MIN((Raw!$A$2:$A$1001=$A8)*(Raw!$R$2:$R$1001="N")*(Raw!$I$2:$I$1001=0)*(Raw!$D$2:$D$1001<$H8)*Raw!$D$2:$D$1001+(1-(Raw!$A$2:$A$1001=$A8)*(Raw!$R$2:$R$1001="N")*(Raw!$I$2:$I$1001=0)*(Raw!$D$2:$D$1001<$H8))*9999))) -> 1 | BT8: =IF(OR($BS8="",$BS8=9999,$BS8=0),"",IFERROR(INDEX(Raw!$N$2:$N$1001,MATCH($A8&"|N|"&$BS8,Raw!$S$2:$S$1001,0)),"")) -> -1.2 | BU8: =IF($B8="","",SUMPRODUCT(MIN((Raw!$A$2:$A$1001=$A8)*(Raw!$R$2:$R$1001="C")*(Raw!$I$2:$I$1001=1)*Raw!$D$2:$D$1001+(1-(Raw!$A$2:$A$1001=$A8)*(Raw!$R$2:$R$1001="C")*(Raw!$I$2:$I$1001=1))*9999))) -> 5 | BV8: =IF(OR($BU8="",$BU8=9999),"",SUMPRODUCT(MIN((Raw!$A$2:$A$1001=$A8)*(Raw!$R$2:$R$1001="C")*(Raw!$I$2:$I$1001=0)*(Raw!$D$2:$D$1001>$BU8)*Raw!$D$2:$D$1001+(1-(Raw!$A$2:$A$1001=$A8)*(Raw!$R$2:$R$1001="C")*(Raw!$I$2:$I$1001=0)*(Raw!$D$2:$D$1001>$BU8))*9999))) -> 6 | BW8: =IF(OR($BV8="",$BV8=9999,$BV8=0),"",IFERROR(INDEX(Raw!$O$2:$O$1001,MATCH($A8&"|C|"&$BV8,Raw!$S$2:$S$1001,0)),"")) -> -25.401 | BX8: =IF($B8="","",IF(ISNUMBER(SEARCH(","&$A8&",",","&SUBSTITUTE(Setup!$B$16," ","")&",")),1,0)) -> 0 | BY8: =IF($B8="","",IF(ISNUMBER(SEARCH(","&$A8&",",","&SUBSTITUTE(Setup!$B$17," ","")&",")),1,0)) -> 0 | BZ8: =IF($AS8="","",IF(Fits!$B$38="Row",$AQ8,IF($AR8="","",$AR8))) | CA8: =IF($AT8="","",IF(Fits!$B$50="Row",$AQ8,IF($AR8="","",$AR8))) | CB8: =IF(OR($D8<>"Drift",$X8="",$A8<IF(Setup!$B$14="",0,Setup!$B$14),Fits!$B$107<3,Fits!$B$110="",Fits!$B$109=0,IF(Fits!$B$38="Row",$AQ8,$AR8)=""),"",IF($BX8=1,IF(OR(Fits!$B$111="",Fits!$B$111=0),"",($X8-(IF(Fits!$B$38="Row",Fits!$B$32,Fits!$B$35)*IF(Fits!$B$38="Row",$AQ8,$AR8)+Fits!$B$110))/(Fits!$B$111*SQRT(1+(1/Fits!$B$107+(IF(Fits!$B$38="Row",$AQ8,$AR8)-Fits!$B$108)^2/Fits!$B$109)))),IF(OR(Fits!$B$107<4,(1/Fits!$B$107+(IF(Fits!$B$38="Row",$AQ8,$AR8)-Fits!$B$108)^2/Fits!$B$109)>=1),"",IF((Fits!$B$116-($X8-(IF(Fits!$B$38="Row",Fits!$B$32,Fits!$B$35)*IF(Fits!$B$38="Row",$AQ8,$AR8)+Fits!$B$110))^2/(1-(1/Fits!$B$107+(IF(Fits!$B$38="Row",$AQ8,$AR8)-Fits!$B$108)^2/Fits!$B$109)))<=0,"",($X8-(IF(Fits!$B$38="Row",Fits!$B$32,Fits!$B$35)*IF(Fits!$B$38="Row",$AQ8,$AR8)+Fits!$B$110))/(SQRT((Fits!$B$116-($X8-(IF(Fits!$B$38="Row",Fits!$B$32,Fits!$B$35)*IF(Fits!$B$38="Row",$AQ8,$AR8)+Fits!$B$110))^2/(1-(1/Fits!$B$107+(IF(Fits!$B$38="Row",$AQ8,$AR8)-Fits!$B$108)^2/Fits!$B$109)))/(Fits!$B$107-3))*SQRT(1-(1/Fits!$B$107+(IF(Fits!$B$38="Row",$AQ8,$AR8)-Fits!$B$108)^2/Fits!$B$109))))))) | CC8: =IF(OR($D8<>"Drift",$AC8="",$A8<IF(Setup!$B$14="",0,Setup!$B$14),Fits!$B$120<3,Fits!$B$123="",Fits!$B$122=0,IF(Fits!$B$50="Row",$AQ8,$AR8)=""),"",IF($BY8=1,IF(OR(Fits!$B$124="",Fits!$B$124=0),"",($AC8-(IF(Fits!$B$50="Row",Fits!$B$44,Fits!$B$47)*IF(Fits!$B$50="Row",$AQ8,$AR8)+Fits!$B$123))/(Fits!$B$124*SQRT(1+(1/Fits!$B$120+(IF(Fits!$B$50="Row",$AQ8,$AR8)-Fits!$B$121)^2/Fits!$B$122)))),IF(OR(Fits!$B$120<4,(1/Fits!$B$120+(IF(Fits!$B$50="Row",$AQ8,$AR8)-Fits!$B$121)^2/Fits!$B$122)>=1),"",IF((Fits!$B$129-($AC8-(IF(Fits!$B$50="Row",Fits!$B$44,Fits!$B$47)*IF(Fits!$B$50="Row",$AQ8,$AR8)+Fits!$B$123))^2/(1-(1/Fits!$B$120+(IF(Fits!$B$50="Row",$AQ8,$AR8)-Fits!$B$121)^2/Fits!$B$122)))<=0,"",($AC8-(IF(Fits!$B$50="Row",Fits!$B$44,Fits!$B$47)*IF(Fits!$B$50="Row",$AQ8,$AR8)+Fits!$B$123))/(SQRT((Fits!$B$129-($AC8-(IF(Fits!$B$50="Row",Fits!$B$44,Fits!$B$47)*IF(Fits!$B$50="Row",$AQ8,$AR8)+Fits!$B$123))^2/(1-(1/Fits!$B$120+(IF(Fits!$B$50="Row",$AQ8,$AR8)-Fits!$B$121)^2/Fits!$B$122)))/(Fits!$B$120-3))*SQRT(1-(1/Fits!$B$120+(IF(Fits!$B$50="Row",$AQ8,$AR8)-Fits!$B$121)^2/Fits!$B$122))))))) | CD8: =IF($AU8="","",1) | CE8: =IF($AU8="","",$AU8-Fits!$B$133) | CF8: =IF($AU8="","",($AV8-(Fits!$B$56*$AU8+Fits!$B$57))-Fits!$B$56*($AU8-Fits!$B$133)) | CG8: =IF($AU8="","",$AU8^2) | CH8: =IF($AW8="","",1) | CI8: =IF($AW8="","",$AW8-Fits!$B$153) | CJ8: =IF($AW8="","",($AX8-(Fits!$B$63*$AW8+Fits!$B$64))-Fits!$B$63*($AW8-Fits!$B$153)) | CK8: =IF($AW8="","",$AW8^2) | CL8: =IF(OR($Z8="",Fits!$B$55<3,Fits!$B$133="",Fits!$B$134="",Fits!$B$134=0,Fits!$B$136=""),"",SQRT((Fits!$B$136*Fits!$B$56)^2+SUMPRODUCT((Fits!$J$163:$J$175*(Fits!$B$163:$B$175/Fits!$B$55+Fits!$H$163:$H$175*($Z8-Fits!$B$133)/Fits!$B$134))^2)+SUMPRODUCT((Fits!$G$163:$G$175*(($Z8-Fits!$B$133)*Fits!$I$163:$I$175/Fits!$B$134-Fits!$B$163:$B$175*Fits!$B$56/Fits!$B$55))^2))) -> 0.24923782 | CM8: =IF($CL8="","",Setup!$B$32*$CL8) -> 0.49847563 | CN8: =IF(OR($AE8="",Fits!$B$62<3,Fits!$B$153="",Fits!$B$154="",Fits!$B$154=0,Fits!$B$156=""),"",SQRT((Fits!$B$156*Fits!$B$63)^2+SUMPRODUCT((Fits!$J$183:$J$195*(Fits!$B$183:$B$195/Fits!$B$62+Fits!$H$183:$H$195*($AE8-Fits!$B$153)/Fits!$B$154))^2)+SUMPRODUCT((Fits!$G$183:$G$195*(($AE8-Fits!$B$153)*Fits!$I$183:$I$195/Fits!$B$154-Fits!$B$183:$B$195*Fits!$B$63/Fits!$B$62))^2))) -> 0.037941441 | CO8: =IF($CN8="","",Setup!$B$32*$CN8) -> 0.075882883 | CP8: =IF(OR(NOT(ISNUMBER($BJ8)),$EK8=1),$CP7,IF($BJ8<=Setup!$B$26,$CP7+1,0)) -> 0 | CQ8: =IF($BT8="","",$A8) -> 3 | CR8: =IF($BW8="","",$A8) -> 3 | CS8: =IF($B8="","",IF(Setup!$A$37="",0,IF(ISNUMBER(SEARCH(Setup!$A$37,$B8)),37,0))) -> 0 | CT8: =IF($B8="","",IF(Setup!$A$38="",0,IF(ISNUMBER(SEARCH(Setup!$A$38,$B8)),38,0))) -> 0 | CU8: =IF($B8="","",IF(Setup!$A$39="",0,IF(ISNUMBER(SEARCH(Setup!$A$39,$B8)),39,0))) -> 0 | CV8: =IF($B8="","",IF(Setup!$A$40="",0,IF(ISNUMBER(SEARCH(Setup!$A$40,$B8)),40,0))) -> 0 | CW8: =IF($B8="","",IF(Setup!$A$41="",0,IF(ISNUMBER(SEARCH(Setup!$A$41,$B8)),41,0))) -> 0 | CX8: =IF($B8="","",IF(Setup!$A$42="",0,IF(ISNUMBER(SEARCH(Setup!$A$42,$B8)),42,0))) -> 0 | CY8: =IF($B8="","",IF(Setup!$A$43="",0,IF(ISNUMBER(SEARCH(Setup!$A$43,$B8)),43,0))) -> 0 | CZ8: =IF($B8="","",IF(Setup!$A$44="",0,IF(ISNUMBER(SEARCH(Setup!$A$44,$B8)),44,0))) -> 44 | DA8: =IF($B8="","",IF(Setup!$A$45="",0,IF(ISNUMBER(SEARCH(Setup!$A$45,$B8)),45,0))) -> 0 | DB8: =IF($B8="","",IF(Setup!$A$46="",0,IF(ISNUMBER(SEARCH(Setup!$A$46,$B8)),46,0))) -> 0 | DC8: =IF($B8="","",IF(Setup!$A$47="",0,IF(ISNUMBER(SEARCH(Setup!$A$47,$B8)),47,0))) -> 0 | DD8: =IF($B8="","",IF(Setup!$A$48="",0,IF(ISNUMBER(SEARCH(Setup!$A$48,$B8)),48,0))) -> 0 | DE8: =IF($B8="","",IF(Setup!$A$49="",0,IF(ISNUMBER(SEARCH(Setup!$A$49,$B8)),49,0))) -> 0 | DF8: =IF($B8="",NA(),$A8) -> 3 | DG8: =IF($BI8="",NA(),$BI8) -> 32.7 | DH8: =IF($N8="",NA(),$N8) -> 36.4 | DI8: =IF(AND($D8="Drift",$N8<>""),$N8,NA()) -> #N/A | DJ8: =IF(AND($D8="Drift",$N8<>""),$N8,"") | DK8: =IF($DJ8="","",$A8) | DL8: =IF($AN8="",NA(),$AM8) -> #N/A | DM8: =IF($AN8="",NA(),$AN8) -> #N/A | DN8: =IF(AND($D8="Sample",$L8<>""),$L8,NA()) -> #N/A | DO8: =IF(AND($D8="Sample",$L8<>"",Fits!$B$98<>""),Fits!$B$98,NA()) -> #N/A | DP8: =IF($AS8="",NA(),$AS8) -> #N/A | DQ8: =IF(AND($D8="Drift",$AS8="",$X8<>""),$X8,NA()) -> #N/A | DR8: =IF(AND($D8="Drift",$Z8<>""),$Z8,NA()) -> #N/A | DS8: =IF(AND(OR($D8="Sample",$D8="Check"),$AA8<>""),$AA8,NA()) -> #N/A | DT8: =IF(OR($B8="",Fits!$B$138=""),NA(),Fits!$B$138) -> 1.76 | DU8: =IF(OR($B8="",Fits!$B$139=""),NA(),Fits!$B$139) -> 20.68 | DV8: =IF($BT8="",NA(),$BT8) -> -1.2 | DW8: =IF($AP8="",NA(),$AO8) -> #N/A | DX8: =IF($AP8="",NA(),$AP8) -> #N/A | DY8: =IF(AND($D8="Sample",$P8<>""),$P8,NA()) -> #N/A | DZ8: =IF(AND($D8="Sample",$P8<>"",Fits!$B$105<>""),Fits!$B$105,NA()) -> #N/A | EA8: =IF($AT8="",NA(),$AT8) -> #N/A | EB8: =IF(AND($D8="Drift",$AT8="",$AC8<>""),$AC8,NA()) -> #N/A | EC8: =IF(AND($D8="Drift",$AE8<>""),$AE8,NA()) -> #N/A | ED8: =IF(AND(OR($D8="Sample",$D8="Check"),$AF8<>""),$AF8,NA()) -> #N/A | EE8: =IF(OR($B8="",Fits!$B$158=""),NA(),Fits!$B$158) -> -40.81 | EF8: =IF(OR($B8="",Fits!$B$159=""),NA(),Fits!$B$159) -> -20.29 | EG8: =IF($BW8="",NA(),$BW8) -> -25.401 | EH8: =IF(AND($EN8=1,ISNUMBER($N8)),$N8,NA()) -> #N/A | EI8: =IF($B8="","",$A8) -> 3 | EJ8: =IF(OR(AND(ISNUMBER($L8),Fits!$B$97>0,$L8>Fits!$B$97),AND(ISNUMBER($P8),Fits!$B$104>0,$P8>Fits!$B$104)),1,0) -> 0 | EK8: =IF(OR($EJ7=1,$EJ6=1),1,0) -> 1 | EL8: =IF(AND($EK8=0,ISNUMBER($N8)),$N8,$EL7) -> 37.2 | EM8: =IF(AND($EK8=1,ISNUMBER($N8),ISNUMBER($EL8)),$N8-$EL8,"") -> -0.8 | EN8: =IF(Setup!$B$28="",0,IF(ISNUMBER($EM8),IF($EM8>Setup!$B$28,1,0),0)) -> 0 | EO8: =IF($EN8=1,COUNTIF($EN$6:$EN8,1),"") | EP8: =IF(AND($EJ7=1,OR($D8="Sample",$D8="Check")),1,0) -> 0 | EQ8: =IF(ISNUMBER($BI8),IF(COUNT($BI$6:$BI8)<=5,$BI8,""),"") -> 32.7 | ER8: =IF(OR(NOT(ISNUMBER($BJ8)),$EK8=1),$ER7,IF($BJ8<=Setup!$B$26,IF($CP7=0,$A8,$ER7),""))
